Workbook

Sheet README
A1: Kota TPS Performance Analysis — Cleaned Workbook
A2: Source | B2: National Power Portal (NPP) Report 02 daily generation reports
A3: Analysis Period | B3: 06-Jun-2026 to 20-Jul-2026 (45 days)
A4: Station | B4: KOTA TPS (1240 MW, 7 units: 2x110, 3x210, 2x195 MW)
A5: Purpose | B5: Consolidated, analysis-ready station-level and unit-level dataset for Excel, SQL, Python and Power BI.
A6: Sheet guide
A7: Master_Data | B7: Original raw extract — untouched. Keep as the audit trail.
A8: Unit_Daily | B8: One row per unit per day (315 rows), with derived KPI columns.
A9: Station_Daily | B9: One row per day for the whole station (45 rows), with derived KPI columns.
A10: Unit_Reference | B10: Static capacity reference per unit.
A11: Data_Dictionary | B11: Every column explained: meaning, unit, how it is calculated.
A12: Data_Quality | B12: Parsing/extraction checks carried over from the raw file.
A13: Pivot_PLF_by_Phase | B13: Unit PLF grouped by the three operating phases.
A14: Pivot_Outage_Loss | B14: Estimated energy loss (MU) by outage cause.
A15: Important | B15: Program Achievement is NOT thermal efficiency. Heat rate / fuel data is not present in Report 02, so true thermal efficiency cannot be calculated from this dataset.
A16: Data Integrity | B16: Raw source values are retained unchanged in Master_Data. Every KPI in Unit_Daily/Station_Daily is a live formula, not a typed-in number.
A17: Estimated Outage Loss | B17: Est_Loss_MU is an ANALYST ESTIMATE: each unit's own non-outage daily average minus its actual generation on outage days. It is not an official utility figure.

Sheet Master_Data
A1: Date | B1: Power Station | C1: Record Type | D1: Unit | E1: Status | F1: Monitored Capacity (MW) | G1: Today's Program (MU) | H1: Today's Actual (MU) | I1: April 1 Till Date Program (MU) | J1: April 1 Till Date Actual (MU) | K1: Coal Stock (Days) | L1: Capacity Under Outage (MW) | M1: Outage Date | N1: Expected/Sync Date | O1: Remarks | P1: Generation Variance (MU) | Q1: Program Achievement (%) | R1: Source File
A2: 46179 | B2: KOTA TPS | C2: Station | F2: 1240 | G2: 23.96 | H2: 22.22 | I2: 1596.76 | J2: 1148.25 | K2: 15 | L2: 0 | P2: -1.74 | Q2: 0.92737896 | R2: dgr2-2026-06-06.xls
A3: 46179 | B3: KOTA TPS | C3: Unit | D3: 1 | F3: 110 | G3: 1.93 | H3: 1.62 | I3: 130.58 | J3: 92.61 | L3: 0 | P3: -0.31 | Q3: 0.83937824 | R3: dgr2-2026-06-06.xls
A4: 46179 | B4: KOTA TPS | C4: Unit | D4: 2 | F4: 110 | G4: 1.93 | H4: 1.66 | I4: 130.58 | J4: 96.36 | L4: 0 | P4: -0.27 | Q4: 0.86010363 | R4: dgr2-2026-06-06.xls
A5: 46179 | B5: KOTA TPS | C5: Unit | D5: 3 | F5: 210 | G5: 3.9 | H5: 3.67 | I5: 264.4 | J5: 207.76 | L5: 0 | P5: -0.23 | Q5: 0.94102564 | R5: dgr2-2026-06-06.xls
A6: 46179 | B6: KOTA TPS | C6: Unit | D6: 4 | F6: 210 | G6: 4 | H6: 3.75 | I6: 262 | J6: 64.96 | L6: 0 | P6: -0.25 | Q6: 0.9375 | R6: dgr2-2026-06-06.xls
A7: 46179 | B7: KOTA TPS | C7: Unit | D7: 5 | F7: 210 | G7: 4 | H7: 3.85 | I7: 266 | J7: 198.7 | L7: 0 | P7: -0.15 | Q7: 0.9625 | R7: dgr2-2026-06-06.xls
A8: 46179 | B8: KOTA TPS | C8: Unit | D8: 6 | F8: 195 | G8: 4.1 | H8: 3.85 | I8: 272.6 | J8: 264.8 | L8: 0 | P8: -0.25 | Q8: 0.93902439 | R8: dgr2-2026-06-06.xls
A9: 46179 | B9: KOTA TPS | C9: Unit | D9: 7 | F9: 195 | G9: 4.1 | H9: 3.82 | I9: 270.6 | J9: 223.06 | L9: 0 | P9: -0.28 | Q9: 0.93170732 | R9: dgr2-2026-06-06.xls
A10: 46180 | B10: KOTA TPS | C10: Station | F10: 1240 | G10: 23.96 | H10: 21.88 | I10: 1620.72 | J10: 1170.13 | K10: 14 | L10: 0 | P10: -2.08 | Q10: 0.91318865 | R10: dgr2-2026-06-07.xls
A11: 46180 | B11: KOTA TPS | C11: Unit | D11: 1 | F11: 110 | G11: 1.93 | H11: 1.61 | I11: 132.51 | J11: 94.22 | L11: 0 | P11: -0.32 | Q11: 0.83419689 | R11: dgr2-2026-06-07.xls
A12: 46180 | B12: KOTA TPS | C12: Unit | D12: 2 | F12: 110 | G12: 1.93 | H12: 1.58 | I12: 132.51 | J12: 97.94 | L12: 0 | P12: -0.35 | Q12: 0.81865285 | R12: dgr2-2026-06-07.xls
A13: 46180 | B13: KOTA TPS | C13: Unit | D13: 3 | F13: 210 | G13: 3.9 | H13: 3.59 | I13: 268.3 | J13: 211.35 | L13: 0 | P13: -0.31 | Q13: 0.92051282 | R13: dgr2-2026-06-07.xls
A14: 46180 | B14: KOTA TPS | C14: Unit | D14: 4 | F14: 210 | G14: 4 | H14: 3.61 | I14: 266 | J14: 68.57 | L14: 0 | P14: -0.39 | Q14: 0.9025 | R14: dgr2-2026-06-07.xls
A15: 46180 | B15: KOTA TPS | C15: Unit | D15: 5 | F15: 210 | G15: 4 | H15: 3.83 | I15: 270 | J15: 202.53 | L15: 0 | P15: -0.17 | Q15: 0.9575 | R15: dgr2-2026-06-07.xls
A16: 46180 | B16: KOTA TPS | C16: Unit | D16: 6 | F16: 195 | G16: 4.1 | H16: 3.85 | I16: 276.7 | J16: 268.65 | L16: 0 | P16: -0.25 | Q16: 0.93902439 | R16: dgr2-2026-06-07.xls
A17: 46180 | B17: KOTA TPS | C17: Unit | D17: 7 | F17: 195 | G17: 4.1 | H17: 3.81 | I17: 274.7 | J17: 226.87 | L17: 0 | P17: -0.29 | Q17: 0.92926829 | R17: dgr2-2026-06-07.xls
A18: 46181 | B18: KOTA TPS | C18: Station | F18: 1240 | G18: 23.96 | H18: 21.95 | I18: 1644.68 | J18: 1192.08 | K18: 14 | L18: 0 | P18: -2.01 | Q18: 0.91611018 | R18: dgr2-2026-06-08.xls
A19: 46181 | B19: KOTA TPS | C19: Unit | D19: 1 | F19: 110 | G19: 1.93 | H19: 1.55 | I19: 134.44 | J19: 95.77 | L19: 0 | P19: -0.38 | Q19: 0.80310881 | R19: dgr2-2026-06-08.xls
A20: 46181 | B20: KOTA TPS | C20: Unit | D20: 2 | F20: 110 | G20: 1.93 | H20: 1.6 | I20: 134.44 | J20: 99.54 | L20: 0 | P20: -0.33 | Q20: 0.82901554 | R20: dgr2-2026-06-08.xls
A21: 46181 | B21: KOTA TPS | C21: Unit | D21: 3 | F21: 210 | G21: 3.9 | H21: 3.61 | I21: 272.2 | J21: 214.96 | L21: 0 | P21: -0.29 | Q21: 0.92564103 | R21: dgr2-2026-06-08.xls
A22: 46181 | B22: KOTA TPS | C22: Unit | D22: 4 | F22: 210 | G22: 4 | H22: 3.67 | I22: 270 | J22: 72.24 | L22: 0 | P22: -0.33 | Q22: 0.9175 | R22: dgr2-2026-06-08.xls
A23: 46181 | B23: KOTA TPS | C23: Unit | D23: 5 | F23: 210 | G23: 4 | H23: 3.85 | I23: 274 | J23: 206.38 | L23: 0 | P23: -0.15 | Q23: 0.9625 | R23: dgr2-2026-06-08.xls
A24: 46181 | B24: KOTA TPS | C24: Unit | D24: 6 | F24: 195 | G24: 4.1 | H24: 3.84 | I24: 280.8 | J24: 272.49 | L24: 0 | P24: -0.26 | Q24: 0.93658537 | R24: dgr2-2026-06-08.xls
A25: 46181 | B25: KOTA TPS | C25: Unit | D25: 7 | F25: 195 | G25: 4.1 | H25: 3.83 | I25: 278.8 | J25: 230.7 | L25: 0 | P25: -0.27 | Q25: 0.93414634 | R25: dgr2-2026-06-08.xls
A26: 46182 | B26: KOTA TPS | C26: Station | F26: 1240 | G26: 23.96 | H26: 22.45 | I26: 1668.64 | J26: 1214.53 | K26: 14 | L26: 0 | P26: -1.51 | Q26: 0.9369783 | R26: dgr2-2026-06-09.xls
A27: 46182 | B27: KOTA TPS | C27: Unit | D27: 1 | F27: 110 | G27: 1.93 | H27: 1.63 | I27: 136.37 | J27: 97.4 | L27: 0 | P27: -0.3 | Q27: 0.84455959 | R27: dgr2-2026-06-09.xls
A28: 46182 | B28: KOTA TPS | C28: Unit | D28: 2 | F28: 110 | G28: 1.93 | H28: 1.74 | I28: 136.37 | J28: 101.28 | L28: 0 | P28: -0.19 | Q28: 0.9015544 | R28: dgr2-2026-06-09.xls
A29: 46182 | B29: KOTA TPS | C29: Unit | D29: 3 | F29: 210 | G29: 3.9 | H29: 3.72 | I29: 276.1 | J29: 218.68 | L29: 0 | P29: -0.18 | Q29: 0.95384615 | R29: dgr2-2026-06-09.xls
A30: 46182 | B30: KOTA TPS | C30: Unit | D30: 4 | F30: 210 | G30: 4 | H30: 3.81 | I30: 274 | J30: 76.05 | L30: 0 | P30: -0.19 | Q30: 0.9525 | R30: dgr2-2026-06-09.xls
A31: 46182 | B31: KOTA TPS | C31: Unit | D31: 5 | F31: 210 | G31: 4 | H31: 3.89 | I31: 278 | J31: 210.27 | L31: 0 | P31: -0.11 | Q31: 0.9725 | R31: dgr2-2026-06-09.xls
A32: 46182 | B32: KOTA TPS | C32: Unit | D32: 6 | F32: 195 | G32: 4.1 | H32: 3.85 | I32: 284.9 | J32: 276.34 | L32: 0 | P32: -0.25 | Q32: 0.93902439 | R32: dgr2-2026-06-09.xls
A33: 46182 | B33: KOTA TPS | C33: Unit | D33: 7 | F33: 195 | G33: 4.1 | H33: 3.81 | I33: 282.9 | J33: 234.51 | L33: 0 | P33: -0.29 | Q33: 0.92926829 | R33: dgr2-2026-06-09.xls
A34: 46183 | B34: KOTA TPS | C34: Station | F34: 1240 | G34: 23.96 | H34: 22.6 | I34: 1692.6 | J34: 1237.13 | K34: 14 | L34: 0 | P34: -1.36 | Q34: 0.94323873 | R34: dgr2-2026-06-10.xls
A35: 46183 | B35: KOTA TPS | C35: Unit | D35: 1 | F35: 110 | G35: 1.93 | H35: 1.65 | I35: 138.3 | J35: 99.05 | L35: 0 | P35: -0.28 | Q35: 0.85492228 | R35: dgr2-2026-06-10.xls
A36: 46183 | B36: KOTA TPS | C36: Unit | D36: 2 | F36: 110 | G36: 1.93 | H36: 1.71 | I36: 138.3 | J36: 102.99 | L36: 0 | P36: -0.22 | Q36: 0.88601036 | R36: dgr2-2026-06-10.xls
A37: 46183 | B37: KOTA TPS | C37: Unit | D37: 3 | F37: 210 | G37: 3.9 | H37: 3.74 | I37: 280 | J37: 222.42 | L37: 0 | P37: -0.16 | Q37: 0.95897436 | R37: dgr2-2026-06-10.xls
A38: 46183 | B38: KOTA TPS | C38: Unit | D38: 4 | F38: 210 | G38: 4 | H38: 3.69 | I38: 278 | J38: 79.74 | L38: 0 | P38: -0.31 | Q38: 0.9225 | R38: dgr2-2026-06-10.xls
A39: 46183 | B39: KOTA TPS | C39: Unit | D39: 5 | F39: 210 | G39: 4 | H39: 3.95 | I39: 282 | J39: 214.22 | L39: 0 | P39: -0.05 | Q39: 0.9875 | R39: dgr2-2026-06-10.xls
A40: 46183 | B40: KOTA TPS | C40: Unit | D40: 6 | F40: 195 | G40: 4.1 | H40: 3.85 | I40: 289 | J40: 280.19 | L40: 0 | P40: -0.25 | Q40: 0.93902439 | R40: dgr2-2026-06-10.xls
...

Sheet Unit_Daily
A1: Date | B1: Unit | C1: Unit_Label | D1: Status | E1: Capacity_MW | F1: Program_MU | G1: Actual_MU | H1: Outage_MW | I1: Outage_DateTime | J1: Sync_DateTime | K1: Remarks | L1: Max_Possible_MU | M1: PLF | N1: Variance_MU | O1: Achievement | P1: Outage_Flag | Q1: ZeroGen_Flag | R1: Month | S1: Week | T1: Phase | U1: Outage_Category | V1: Baseline_MU | W1: Est_Loss_MU
A2: 46179 | B2: 1 | C2: ="Unit "&B2 -> Unit 1 | E2: 110 | F2: 1.93 | G2: 1.62 | H2: 0 | L2: =E2*24/1000 -> 2.64 | M2: =G2/L2 -> 0.61363636 | N2: =G2-F2 -> -0.31 | O2: =IF(F2=0,"",G2/F2) -> 0.83937824 | P2: =IF(H2>0,1,0) -> 0 | Q2: =IF(G2=0,1,0) -> 0 | R2: =TEXT(A2,"mmm") -> Jun | S2: =WEEKNUM(A2,2) -> 23 | T2: =IF(A2<DATE(2026,6,30),"1-Pre-outage",IF(A2<DATE(2026,7,5),"2-Transition","3-Outage-heavy")) -> 1-Pre-outage | U2: =IF(K2="","",IF(ISNUMBER(SEARCH("TURBINE",K2)),"Turbine",IF(ISNUMBER(SEARCH("GENERATOR",K2)),"Generator",IF(ISNUMBER(SEARCH("BOILER",K2)),"Boiler",IF(ISNUMBER(SEARCH("AIR PREHEATER",K2)),"Auxiliary",IF(ISNUMBER(SEARCH("ELECTRICAL",K2)),"Electrical","Other")))))) | V2: =AVERAGEIFS(G:G,B:B,B2,H:H,0) -> 1.6118182 | W2: =IF(P2=1,MAX(0,V2-G2),0) -> 0
A3: 46179 | B3: 2 | C3: ="Unit "&B3 -> Unit 2 | E3: 110 | F3: 1.93 | G3: 1.66 | H3: 0 | L3: =E3*24/1000 -> 2.64 | M3: =G3/L3 -> 0.62878788 | N3: =G3-F3 -> -0.27 | O3: =IF(F3=0,"",G3/F3) -> 0.86010363 | P3: =IF(H3>0,1,0) -> 0 | Q3: =IF(G3=0,1,0) -> 0 | R3: =TEXT(A3,"mmm") -> Jun | S3: =WEEKNUM(A3,2) -> 23 | T3: =IF(A3<DATE(2026,6,30),"1-Pre-outage",IF(A3<DATE(2026,7,5),"2-Transition","3-Outage-heavy")) -> 1-Pre-outage | U3: =IF(K3="","",IF(ISNUMBER(SEARCH("TURBINE",K3)),"Turbine",IF(ISNUMBER(SEARCH("GENERATOR",K3)),"Generator",IF(ISNUMBER(SEARCH("BOILER",K3)),"Boiler",IF(ISNUMBER(SEARCH("AIR PREHEATER",K3)),"Auxiliary",IF(ISNUMBER(SEARCH("ELECTRICAL",K3)),"Electrical","Other")))))) | V3: =AVERAGEIFS(G:G,B:B,B3,H:H,0) -> 1.6795556 | W3: =IF(P3=1,MAX(0,V3-G3),0) -> 0
A4: 46179 | B4: 3 | C4: ="Unit "&B4 -> Unit 3 | E4: 210 | F4: 3.9 | G4: 3.67 | H4: 0 | L4: =E4*24/1000 -> 5.04 | M4: =G4/L4 -> 0.7281746 | N4: =G4-F4 -> -0.23 | O4: =IF(F4=0,"",G4/F4) -> 0.94102564 | P4: =IF(H4>0,1,0) -> 0 | Q4: =IF(G4=0,1,0) -> 0 | R4: =TEXT(A4,"mmm") -> Jun | S4: =WEEKNUM(A4,2) -> 23 | T4: =IF(A4<DATE(2026,6,30),"1-Pre-outage",IF(A4<DATE(2026,7,5),"2-Transition","3-Outage-heavy")) -> 1-Pre-outage | U4: =IF(K4="","",IF(ISNUMBER(SEARCH("TURBINE",K4)),"Turbine",IF(ISNUMBER(SEARCH("GENERATOR",K4)),"Generator",IF(ISNUMBER(SEARCH("BOILER",K4)),"Boiler",IF(ISNUMBER(SEARCH("AIR PREHEATER",K4)),"Auxiliary",IF(ISNUMBER(SEARCH("ELECTRICAL",K4)),"Electrical","Other")))))) | V4: =AVERAGEIFS(G:G,B:B,B4,H:H,0) -> 3.7269767 | W4: =IF(P4=1,MAX(0,V4-G4),0) -> 0
A5: 46179 | B5: 4 | C5: ="Unit "&B5 -> Unit 4 | E5: 210 | F5: 4 | G5: 3.75 | H5: 0 | L5: =E5*24/1000 -> 5.04 | M5: =G5/L5 -> 0.74404762 | N5: =G5-F5 -> -0.25 | O5: =IF(F5=0,"",G5/F5) -> 0.9375 | P5: =IF(H5>0,1,0) -> 0 | Q5: =IF(G5=0,1,0) -> 0 | R5: =TEXT(A5,"mmm") -> Jun | S5: =WEEKNUM(A5,2) -> 23 | T5: =IF(A5<DATE(2026,6,30),"1-Pre-outage",IF(A5<DATE(2026,7,5),"2-Transition","3-Outage-heavy")) -> 1-Pre-outage | U5: =IF(K5="","",IF(ISNUMBER(SEARCH("TURBINE",K5)),"Turbine",IF(ISNUMBER(SEARCH("GENERATOR",K5)),"Generator",IF(ISNUMBER(SEARCH("BOILER",K5)),"Boiler",IF(ISNUMBER(SEARCH("AIR PREHEATER",K5)),"Auxiliary",IF(ISNUMBER(SEARCH("ELECTRICAL",K5)),"Electrical","Other")))))) | V5: =AVERAGEIFS(G:G,B:B,B5,H:H,0) -> 3.5358621 | W5: =IF(P5=1,MAX(0,V5-G5),0) -> 0
A6: 46179 | B6: 5 | C6: ="Unit "&B6 -> Unit 5 | E6: 210 | F6: 4 | G6: 3.85 | H6: 0 | L6: =E6*24/1000 -> 5.04 | M6: =G6/L6 -> 0.76388889 | N6: =G6-F6 -> -0.15 | O6: =IF(F6=0,"",G6/F6) -> 0.9625 | P6: =IF(H6>0,1,0) -> 0 | Q6: =IF(G6=0,1,0) -> 0 | R6: =TEXT(A6,"mmm") -> Jun | S6: =WEEKNUM(A6,2) -> 23 | T6: =IF(A6<DATE(2026,6,30),"1-Pre-outage",IF(A6<DATE(2026,7,5),"2-Transition","3-Outage-heavy")) -> 1-Pre-outage | U6: =IF(K6="","",IF(ISNUMBER(SEARCH("TURBINE",K6)),"Turbine",IF(ISNUMBER(SEARCH("GENERATOR",K6)),"Generator",IF(ISNUMBER(SEARCH("BOILER",K6)),"Boiler",IF(ISNUMBER(SEARCH("AIR PREHEATER",K6)),"Auxiliary",IF(ISNUMBER(SEARCH("ELECTRICAL",K6)),"Electrical","Other")))))) | V6: =AVERAGEIFS(G:G,B:B,B6,H:H,0) -> 3.9888889 | W6: =IF(P6=1,MAX(0,V6-G6),0) -> 0
A7: 46179 | B7: 6 | C7: ="Unit "&B7 -> Unit 6 | E7: 195 | F7: 4.1 | G7: 3.85 | H7: 0 | L7: =E7*24/1000 -> 4.68 | M7: =G7/L7 -> 0.82264957 | N7: =G7-F7 -> -0.25 | O7: =IF(F7=0,"",G7/F7) -> 0.93902439 | P7: =IF(H7>0,1,0) -> 0 | Q7: =IF(G7=0,1,0) -> 0 | R7: =TEXT(A7,"mmm") -> Jun | S7: =WEEKNUM(A7,2) -> 23 | T7: =IF(A7<DATE(2026,6,30),"1-Pre-outage",IF(A7<DATE(2026,7,5),"2-Transition","3-Outage-heavy")) -> 1-Pre-outage | U7: =IF(K7="","",IF(ISNUMBER(SEARCH("TURBINE",K7)),"Turbine",IF(ISNUMBER(SEARCH("GENERATOR",K7)),"Generator",IF(ISNUMBER(SEARCH("BOILER",K7)),"Boiler",IF(ISNUMBER(SEARCH("AIR PREHEATER",K7)),"Auxiliary",IF(ISNUMBER(SEARCH("ELECTRICAL",K7)),"Electrical","Other")))))) | V7: =AVERAGEIFS(G:G,B:B,B7,H:H,0) -> 3.8537778 | W7: =IF(P7=1,MAX(0,V7-G7),0) -> 0
A8: 46179 | B8: 7 | C8: ="Unit "&B8 -> Unit 7 | E8: 195 | F8: 4.1 | G8: 3.82 | H8: 0 | L8: =E8*24/1000 -> 4.68 | M8: =G8/L8 -> 0.81623932 | N8: =G8-F8 -> -0.28 | O8: =IF(F8=0,"",G8/F8) -> 0.93170732 | P8: =IF(H8>0,1,0) -> 0 | Q8: =IF(G8=0,1,0) -> 0 | R8: =TEXT(A8,"mmm") -> Jun | S8: =WEEKNUM(A8,2) -> 23 | T8: =IF(A8<DATE(2026,6,30),"1-Pre-outage",IF(A8<DATE(2026,7,5),"2-Transition","3-Outage-heavy")) -> 1-Pre-outage | U8: =IF(K8="","",IF(ISNUMBER(SEARCH("TURBINE",K8)),"Turbine",IF(ISNUMBER(SEARCH("GENERATOR",K8)),"Generator",IF(ISNUMBER(SEARCH("BOILER",K8)),"Boiler",IF(ISNUMBER(SEARCH("AIR PREHEATER",K8)),"Auxiliary",IF(ISNUMBER(SEARCH("ELECTRICAL",K8)),"Electrical","Other")))))) | V8: =AVERAGEIFS(G:G,B:B,B8,H:H,0) -> 3.98375 | W8: =IF(P8=1,MAX(0,V8-G8),0) -> 0
A9: 46180 | B9: 1 | C9: ="Unit "&B9 -> Unit 1 | E9: 110 | F9: 1.93 | G9: 1.61 | H9: 0 | L9: =E9*24/1000 -> 2.64 | M9: =G9/L9 -> 0.60984848 | N9: =G9-F9 -> -0.32 | O9: =IF(F9=0,"",G9/F9) -> 0.83419689 | P9: =IF(H9>0,1,0) -> 0 | Q9: =IF(G9=0,1,0) -> 0 | R9: =TEXT(A9,"mmm") -> Jun | S9: =WEEKNUM(A9,2) -> 23 | T9: =IF(A9<DATE(2026,6,30),"1-Pre-outage",IF(A9<DATE(2026,7,5),"2-Transition","3-Outage-heavy")) -> 1-Pre-outage | U9: =IF(K9="","",IF(ISNUMBER(SEARCH("TURBINE",K9)),"Turbine",IF(ISNUMBER(SEARCH("GENERATOR",K9)),"Generator",IF(ISNUMBER(SEARCH("BOILER",K9)),"Boiler",IF(ISNUMBER(SEARCH("AIR PREHEATER",K9)),"Auxiliary",IF(ISNUMBER(SEARCH("ELECTRICAL",K9)),"Electrical","Other")))))) | V9: =AVERAGEIFS(G:G,B:B,B9,H:H,0) -> 1.6118182 | W9: =IF(P9=1,MAX(0,V9-G9),0) -> 0
A10: 46180 | B10: 2 | C10: ="Unit "&B10 -> Unit 2 | E10: 110 | F10: 1.93 | G10: 1.58 | H10: 0 | L10: =E10*24/1000 -> 2.64 | M10: =G10/L10 -> 0.59848485 | N10: =G10-F10 -> -0.35 | O10: =IF(F10=0,"",G10/F10) -> 0.81865285 | P10: =IF(H10>0,1,0) -> 0 | Q10: =IF(G10=0,1,0) -> 0 | R10: =TEXT(A10,"mmm") -> Jun | S10: =WEEKNUM(A10,2) -> 23 | T10: =IF(A10<DATE(2026,6,30),"1-Pre-outage",IF(A10<DATE(2026,7,5),"2-Transition","3-Outage-heavy")) -> 1-Pre-outage | U10: =IF(K10="","",IF(ISNUMBER(SEARCH("TURBINE",K10)),"Turbine",IF(ISNUMBER(SEARCH("GENERATOR",K10)),"Generator",IF(ISNUMBER(SEARCH("BOILER",K10)),"Boiler",IF(ISNUMBER(SEARCH("AIR PREHEATER",K10)),"Auxiliary",IF(ISNUMBER(SEARCH("ELECTRICAL",K10)),"Electrical","Other")))))) | V10: =AVERAGEIFS(G:G,B:B,B10,H:H,0) -> 1.6795556 | W10: =IF(P10=1,MAX(0,V10-G10),0) -> 0
A11: 46180 | B11: 3 | C11: ="Unit "&B11 -> Unit 3 | E11: 210 | F11: 3.9 | G11: 3.59 | H11: 0 | L11: =E11*24/1000 -> 5.04 | M11: =G11/L11 -> 0.71230159 | N11: =G11-F11 -> -0.31 | O11: =IF(F11=0,"",G11/F11) -> 0.92051282 | P11: =IF(H11>0,1,0) -> 0 | Q11: =IF(G11=0,1,0) -> 0 | R11: =TEXT(A11,"mmm") -> Jun | S11: =WEEKNUM(A11,2) -> 23 | T11: =IF(A11<DATE(2026,6,30),"1-Pre-outage",IF(A11<DATE(2026,7,5),"2-Transition","3-Outage-heavy")) -> 1-Pre-outage | U11: =IF(K11="","",IF(ISNUMBER(SEARCH("TURBINE",K11)),"Turbine",IF(ISNUMBER(SEARCH("GENERATOR",K11)),"Generator",IF(ISNUMBER(SEARCH("BOILER",K11)),"Boiler",IF(ISNUMBER(SEARCH("AIR PREHEATER",K11)),"Auxiliary",IF(ISNUMBER(SEARCH("ELECTRICAL",K11)),"Electrical","Other")))))) | V11: =AVERAGEIFS(G:G,B:B,B11,H:H,0) -> 3.7269767 | W11: =IF(P11=1,MAX(0,V11-G11),0) -> 0
A12: 46180 | B12: 4 | C12: ="Unit "&B12 -> Unit 4 | E12: 210 | F12: 4 | G12: 3.61 | H12: 0 | L12: =E12*24/1000 -> 5.04 | M12: =G12/L12 -> 0.71626984 | N12: =G12-F12 -> -0.39 | O12: =IF(F12=0,"",G12/F12) -> 0.9025 | P12: =IF(H12>0,1,0) -> 0 | Q12: =IF(G12=0,1,0) -> 0 | R12: =TEXT(A12,"mmm") -> Jun | S12: =WEEKNUM(A12,2) -> 23 | T12: =IF(A12<DATE(2026,6,30),"1-Pre-outage",IF(A12<DATE(2026,7,5),"2-Transition","3-Outage-heavy")) -> 1-Pre-outage | U12: =IF(K12="","",IF(ISNUMBER(SEARCH("TURBINE",K12)),"Turbine",IF(ISNUMBER(SEARCH("GENERATOR",K12)),"Generator",IF(ISNUMBER(SEARCH("BOILER",K12)),"Boiler",IF(ISNUMBER(SEARCH("AIR PREHEATER",K12)),"Auxiliary",IF(ISNUMBER(SEARCH("ELECTRICAL",K12)),"Electrical","Other")))))) | V12: =AVERAGEIFS(G:G,B:B,B12,H:H,0) -> 3.5358621 | W12: =IF(P12=1,MAX(0,V12-G12),0) -> 0
A13: 46180 | B13: 5 | C13: ="Unit "&B13 -> Unit 5 | E13: 210 | F13: 4 | G13: 3.83 | H13: 0 | L13: =E13*24/1000 -> 5.04 | M13: =G13/L13 -> 0.75992063 | N13: =G13-F13 -> -0.17 | O13: =IF(F13=0,"",G13/F13) -> 0.9575 | P13: =IF(H13>0,1,0) -> 0 | Q13: =IF(G13=0,1,0) -> 0 | R13: =TEXT(A13,"mmm") -> Jun | S13: =WEEKNUM(A13,2) -> 23 | T13: =IF(A13<DATE(2026,6,30),"1-Pre-outage",IF(A13<DATE(2026,7,5),"2-Transition","3-Outage-heavy")) -> 1-Pre-outage | U13: =IF(K13="","",IF(ISNUMBER(SEARCH("TURBINE",K13)),"Turbine",IF(ISNUMBER(SEARCH("GENERATOR",K13)),"Generator",IF(ISNUMBER(SEARCH("BOILER",K13)),"Boiler",IF(ISNUMBER(SEARCH("AIR PREHEATER",K13)),"Auxiliary",IF(ISNUMBER(SEARCH("ELECTRICAL",K13)),"Electrical","Other")))))) | V13: =AVERAGEIFS(G:G,B:B,B13,H:H,0) -> 3.9888889 | W13: =IF(P13=1,MAX(0,V13-G13),0) -> 0
... A175: 46203 | B175: 6 | C175: ="Unit "&B175 -> Unit 6 | E175: 195 | F175: 4.1 | G175: 3.85 | H175: 0 | L175: =E175*24/1000 -> 4.68 | M175: =G175/L175 -> 0.82264957 | N175: =G175-F175 -> -0.25 | O175: =IF(F175=0,"",G175/F175) -> 0.93902439 | P175: =IF(H175>0,1,0) -> 0 | Q175: =IF(G175=0,1,0) -> 0 | R175: =TEXT(A175,"mmm") -> Jun | S175: =WEEKNUM(A175,2) -> 27 | T175: =IF(A175<DATE(2026,6,30),"1-Pre-outage",IF(A175<DATE(2026,7,5),"2-Transition","3-Outage-heavy")) -> 2-Transition | U175: =IF(K175="","",IF(ISNUMBER(SEARCH("TURBINE",K175)),"Turbine",IF(ISNUMBER(SEARCH("GENERATOR",K175)),"Generator",IF(ISNUMBER(SEARCH("BOILER",K175)),"Boiler",IF(ISNUMBER(SEARCH("AIR PREHEATER",K175)),"Auxiliary",IF(ISNUMBER(SEARCH("ELECTRICAL",K175)),"Electrical","Other")))))) | V175: =AVERAGEIFS(G:G,B:B,B175,H:H,0) -> 3.8537778 | W175: =IF(P175=1,MAX(0,V175-G175),0) -> 0
A176: 46203 | B176: 7 | C176: ="Unit "&B176 -> Unit 7 | D176: S | E176: 195 | F176: 4.1 | G176: 3.31 | H176: 195 | I176: 46203.82 | K176: AIR PREHEATERS PROBLEM | L176: =E176*24/1000 -> 4.68 | M176: =G176/L176 -> 0.70726496 | N176: =G176-F176 -> -0.79 | O176: =IF(F176=0,"",G176/F176) -> 0.80731707 | P176: =IF(H176>0,1,0) -> 1 | Q176: =IF(G176=0,1,0) -> 0 | R176: =TEXT(A176,"mmm") -> Jun | S176: =WEEKNUM(A176,2) -> 27 | T176: =IF(A176<DATE(2026,6,30),"1-Pre-outage",IF(A176<DATE(2026,7,5),"2-Transition","3-Outage-heavy")) -> 2-Transition | U176: =IF(K176="","",IF(ISNUMBER(SEARCH("TURBINE",K176)),"Turbine",IF(ISNUMBER(SEARCH("GENERATOR",K176)),"Generator",IF(ISNUMBER(SEARCH("BOILER",K176)),"Boiler",IF(ISNUMBER(SEARCH("AIR PREHEATER",K176)),"Auxiliary",IF(ISNUMBER(SEARCH("ELECTRICAL",K176)),"Electrical","Other")))))) -> Auxiliary | V176: =AVERAGEIFS(G:G,B:B,B176,H:H,0) -> 3.98375 | W176: =IF(P176=1,MAX(0,V176-G176),0) -> 0.67375
A177: 46204 | B177: 1 | C177: ="Unit "&B177 -> Unit 1 | E177: 110 | F177: 1.84 | G177: 1.71 | H177: 0 | L177: =E177*24/1000 -> 2.64 | M177: =G177/L177 -> 0.64772727 | N177: =G177-F177 -> -0.13 | O177: =IF(F177=0,"",G177/F177) -> 0.92934783 | P177: =IF(H177>0,1,0) -> 0 | Q177: =IF(G177=0,1,0) -> 0 | R177: =TEXT(A177,"mmm") -> Jul | S177: =WEEKNUM(A177,2) -> 27 | T177: =IF(A177<DATE(2026,6,30),"1-Pre-outage",IF(A177<DATE(2026,7,5),"2-Transition","3-Outage-heavy")) -> 2-Transition | U177: =IF(K177="","",IF(ISNUMBER(SEARCH("TURBINE",K177)),"Turbine",IF(ISNUMBER(SEARCH("GENERATOR",K177)),"Generator",IF(ISNUMBER(SEARCH("BOILER",K177)),"Boiler",IF(ISNUMBER(SEARCH("AIR PREHEATER",K177)),"Auxiliary",IF(ISNUMBER(SEARCH("ELECTRICAL",K177)),"Electrical","Other")))))) | V177: =AVERAGEIFS(G:G,B:B,B177,H:H,0) -> 1.6118182 | W177: =IF(P177=1,MAX(0,V177-G177),0) -> 0
A178: 46204 | B178: 2 | C178: ="Unit "&B178 -> Unit 2 | E178: 110 | F178: 1.87 | G178: 1.74 | H178: 0 | L178: =E178*24/1000 -> 2.64 | M178: =G178/L178 -> 0.65909091 | N178: =G178-F178 -> -0.13 | O178: =IF(F178=0,"",G178/F178) -> 0.93048128 | P178: =IF(H178>0,1,0) -> 0 | Q178: =IF(G178=0,1,0) -> 0 | R178: =TEXT(A178,"mmm") -> Jul | S178: =WEEKNUM(A178,2) -> 27 | T178: =IF(A178<DATE(2026,6,30),"1-Pre-outage",IF(A178<DATE(2026,7,5),"2-Transition","3-Outage-heavy")) -> 2-Transition | U178: =IF(K178="","",IF(ISNUMBER(SEARCH("TURBINE",K178)),"Turbine",IF(ISNUMBER(SEARCH("GENERATOR",K178)),"Generator",IF(ISNUMBER(SEARCH("BOILER",K178)),"Boiler",IF(ISNUMBER(SEARCH("AIR PREHEATER",K178)),"Auxiliary",IF(ISNUMBER(SEARCH("ELECTRICAL",K178)),"Electrical","Other")))))) | V178: =AVERAGEIFS(G:G,B:B,B178,H:H,0) -> 1.6795556 | W178: =IF(P178=1,MAX(0,V178-G178),0) -> 0
A179: 46204 | B179: 3 | C179: ="Unit "&B179 -> Unit 3 | E179: 210 | F179: 3.67 | G179: 3.82 | H179: 0 | L179: =E179*24/1000 -> 5.04 | M179: =G179/L179 -> 0.75793651 | N179: =G179-F179 -> 0.15 | O179: =IF(F179=0,"",G179/F179) -> 1.0408719 | P179: =IF(H179>0,1,0) -> 0 | Q179: =IF(G179=0,1,0) -> 0 | R179: =TEXT(A179,"mmm") -> Jul | S179: =WEEKNUM(A179,2) -> 27 | T179: =IF(A179<DATE(2026,6,30),"1-Pre-outage",IF(A179<DATE(2026,7,5),"2-Transition","3-Outage-heavy")) -> 2-Transition | U179: =IF(K179="","",IF(ISNUMBER(SEARCH("TURBINE",K179)),"Turbine",IF(ISNUMBER(SEARCH("GENERATOR",K179)),"Generator",IF(ISNUMBER(SEARCH("BOILER",K179)),"Boiler",IF(ISNUMBER(SEARCH("AIR PREHEATER",K179)),"Auxiliary",IF(ISNUMBER(SEARCH("ELECTRICAL",K179)),"Electrical","Other")))))) | V179: =AVERAGEIFS(G:G,B:B,B179,H:H,0) -> 3.7269767 | W179: =IF(P179=1,MAX(0,V179-G179),0) -> 0
A180: 46204 | B180: 4 | C180: ="Unit "&B180 -> Unit 4 | E180: 210 | F180: 0 | G180: 3.63 | H180: 0 | L180: =E180*24/1000 -> 5.04 | M180: =G180/L180 -> 0.7202381 | N180: =G180-F180 -> 3.63 | O180: =IF(F180=0,"",G180/F180) | P180: =IF(H180>0,1,0) -> 0 | Q180: =IF(G180=0,1,0) -> 0 | R180: =TEXT(A180,"mmm") -> Jul | S180: =WEEKNUM(A180,2) -> 27 | T180: =IF(A180<DATE(2026,6,30),"1-Pre-outage",IF(A180<DATE(2026,7,5),"2-Transition","3-Outage-heavy")) -> 2-Transition | U180: =IF(K180="","",IF(ISNUMBER(SEARCH("TURBINE",K180)),"Turbine",IF(ISNUMBER(SEARCH("GENERATOR",K180)),"Generator",IF(ISNUMBER(SEARCH("BOILER",K180)),"Boiler",IF(ISNUMBER(SEARCH("AIR PREHEATER",K180)),"Auxiliary",IF(ISNUMBER(SEARCH("ELECTRICAL",K180)),"Electrical","Other")))))) | V180: =AVERAGEIFS(G:G,B:B,B180,H:H,0) -> 3.5358621 | W180: =IF(P180=1,MAX(0,V180-G180),0) -> 0
A181: 46204 | B181: 5 | C181: ="Unit "&B181 -> Unit 5 | E181: 210 | F181: 3.81 | G181: 4.06 | H181: 0 | L181: =E181*24/1000 -> 5.04 | M181: =G181/L181 -> 0.80555556 | N181: =G181-F181 -> 0.25 | O181: =IF(F181=0,"",G181/F181) -> 1.0656168 | P181: =IF(H181>0,1,0) -> 0 | Q181: =IF(G181=0,1,0) -> 0 | R181: =TEXT(A181,"mmm") -> Jul | S181: =WEEKNUM(A181,2) -> 27 | T181: =IF(A181<DATE(2026,6,30),"1-Pre-outage",IF(A181<DATE(2026,7,5),"2-Transition","3-Outage-heavy")) -> 2-Transition | U181: =IF(K181="","",IF(ISNUMBER(SEARCH("TURBINE",K181)),"Turbine",IF(ISNUMBER(SEARCH("GENERATOR",K181)),"Generator",IF(ISNUMBER(SEARCH("BOILER",K181)),"Boiler",IF(ISNUMBER(SEARCH("AIR PREHEATER",K181)),"Auxiliary",IF(ISNUMBER(SEARCH("ELECTRICAL",K181)),"Electrical","Other")))))) | V181: =AVERAGEIFS(G:G,B:B,B181,H:H,0) -> 3.9888889 | W181: =IF(P181=1,MAX(0,V181-G181),0) -> 0
A182: 46204 | B182: 6 | C182: ="Unit "&B182 -> Unit 6 | E182: 195 | F182: 3.84 | G182: 3.86 | H182: 0 | L182: =E182*24/1000 -> 4.68 | M182: =G182/L182 -> 0.82478632 | N182: =G182-F182 -> 0.02 | O182: =IF(F182=0,"",G182/F182) -> 1.0052083 | P182: =IF(H182>0,1,0) -> 0 | Q182: =IF(G182=0,1,0) -> 0 | R182: =TEXT(A182,"mmm") -> Jul | S182: =WEEKNUM(A182,2) -> 27 | T182: =IF(A182<DATE(2026,6,30),"1-Pre-outage",IF(A182<DATE(2026,7,5),"2-Transition","3-Outage-heavy")) -> 2-Transition | U182: =IF(K182="","",IF(ISNUMBER(SEARCH("TURBINE",K182)),"Turbine",IF(ISNUMBER(SEARCH("GENERATOR",K182)),"Generator",IF(ISNUMBER(SEARCH("BOILER",K182)),"Boiler",IF(ISNUMBER(SEARCH("AIR PREHEATER",K182)),"Auxiliary",IF(ISNUMBER(SEARCH("ELECTRICAL",K182)),"Electrical","Other")))))) | V182: =AVERAGEIFS(G:G,B:B,B182,H:H,0) -> 3.8537778 | W182: =IF(P182=1,MAX(0,V182-G182),0) -> 0
A183: 46204 | B183: 7 | C183: ="Unit "&B183 -> Unit 7 | D183: * | E183: 195 | F183: 0 | G183: 3.28 | H183: 195 | I183: 46203.82 | J183: 46204.149 | K183: AIR PREHEATERS PROBLEM | L183: =E183*24/1000 -> 4.68 | M183: =G183/L183 -> 0.7008547 | N183: =G183-F183 -> 3.28 | O183: =IF(F183=0,"",G183/F183) | P183: =IF(H183>0,1,0) -> 1 | Q183: =IF(G183=0,1,0) -> 0 | R183: =TEXT(A183,"mmm") -> Jul | S183: =WEEKNUM(A183,2) -> 27 | T183: =IF(A183<DATE(2026,6,30),"1-Pre-outage",IF(A183<DATE(2026,7,5),"2-Transition","3-Outage-heavy")) -> 2-Transition | U183: =IF(K183="","",IF(ISNUMBER(SEARCH("TURBINE",K183)),"Turbine",IF(ISNUMBER(SEARCH("GENERATOR",K183)),"Generator",IF(ISNUMBER(SEARCH("BOILER",K183)),"Boiler",IF(ISNUMBER(SEARCH("AIR PREHEATER",K183)),"Auxiliary",IF(ISNUMBER(SEARCH("ELECTRICAL",K183)),"Electrical","Other")))))) -> Auxiliary | V183: =AVERAGEIFS(G:G,B:B,B183,H:H,0) -> 3.98375 | W183: =IF(P183=1,MAX(0,V183-G183),0) -> 0.70375
A184: 46205 | B184: 1 | C184: ="Unit "&B184 -> Unit 1 | E184: 110 | F184: 1.84 | G184: 1.71 | H184: 0 | L184: =E184*24/1000 -> 2.64 | M184: =G184/L184 -> 0.64772727 | N184: =G184-F184 -> -0.13 | O184: =IF(F184=0,"",G184/F184) -> 0.92934783 | P184: =IF(H184>0,1,0) -> 0 | Q184: =IF(G184=0,1,0) -> 0 | R184: =TEXT(A184,"mmm") -> Jul | S184: =WEEKNUM(A184,2) -> 27 | T184: =IF(A184<DATE(2026,6,30),"1-Pre-outage",IF(A184<DATE(2026,7,5),"2-Transition","3-Outage-heavy")) -> 2-Transition | U184: =IF(K184="","",IF(ISNUMBER(SEARCH("TURBINE",K184)),"Turbine",IF(ISNUMBER(SEARCH("GENERATOR",K184)),"Generator",IF(ISNUMBER(SEARCH("BOILER",K184)),"Boiler",IF(ISNUMBER(SEARCH("AIR PREHEATER",K184)),"Auxiliary",IF(ISNUMBER(SEARCH("ELECTRICAL",K184)),"Electrical","Other")))))) | V184: =AVERAGEIFS(G:G,B:B,B184,H:H,0) -> 1.6118182 | W184: =IF(P184=1,MAX(0,V184-G184),0) -> 0
A185: 46205 | B185: 2 | C185: ="Unit "&B185 -> Unit 2 | E185: 110 | F185: 1.87 | G185: 1.76 | H185: 0 | L185: =E185*24/1000 -> 2.64 | M185: =G185/L185 -> 0.66666667 | N185: =G185-F185 -> -0.11 | O185: =IF(F185=0,"",G185/F185) -> 0.94117647 | P185: =IF(H185>0,1,0) -> 0 | Q185: =IF(G185=0,1,0) -> 0 | R185: =TEXT(A185,"mmm") -> Jul | S185: =WEEKNUM(A185,2) -> 27 | T185: =IF(A185<DATE(2026,6,30),"1-Pre-outage",IF(A185<DATE(2026,7,5),"2-Transition","3-Outage-heavy")) -> 2-Transition | U185: =IF(K185="","",IF(ISNUMBER(SEARCH("TURBINE",K185)),"Turbine",IF(ISNUMBER(SEARCH("GENERATOR",K185)),"Generator",IF(ISNUMBER(SEARCH("BOILER",K185)),"Boiler",IF(ISNUMBER(SEARCH("AIR PREHEATER",K185)),"Auxiliary",IF(ISNUMBER(SEARCH("ELECTRICAL",K185)),"Electrical","Other")))))) | V185: =AVERAGEIFS(G:G,B:B,B185,H:H,0) -> 1.6795556 | W185: =IF(P185=1,MAX(0,V185-G185),0) -> 0
A186: 46205 | B186: 3 | C186: ="Unit "&B186 -> Unit 3 | E186: 210 | F186: 3.67 | G186: 3.82 | H186: 0 | L186: =E186*24/1000 -> 5.04 | M186: =G186/L186 -> 0.75793651 | N186: =G186-F186 -> 0.15 | O186: =IF(F186=0,"",G186/F186) -> 1.0408719 | P186: =IF(H186>0,1,0) -> 0 | Q186: =IF(G186=0,1,0) -> 0 | R186: =TEXT(A186,"mmm") -> Jul | S186: =WEEKNUM(A186,2) -> 27 | T186: =IF(A186<DATE(2026,6,30),"1-Pre-outage",IF(A186<DATE(2026,7,5),"2-Transition","3-Outage-heavy")) -> 2-Transition | U186: =IF(K186="","",IF(ISNUMBER(SEARCH("TURBINE",K186)),"Turbine",IF(ISNUMBER(SEARCH("GENERATOR",K186)),"Generator",IF(ISNUMBER(SEARCH("BOILER",K186)),"Boiler",IF(ISNUMBER(SEARCH("AIR PREHEATER",K186)),"Auxiliary",IF(ISNUMBER(SEARCH("ELECTRICAL",K186)),"Electrical","Other")))))) | V186: =AVERAGEIFS(G:G,B:B,B186,H:H,0) -> 3.7269767 | W186: =IF(P186=1,MAX(0,V186-G186),0) -> 0
A187: 46205 | B187: 4 | C187: ="Unit "&B187 -> Unit 4 | E187: 210 | F187: 0 | G187: 3.58 | H187: 0 | L187: =E187*24/1000 -> 5.04 | M187: =G187/L187 -> 0.71031746 | N187: =G187-F187 -> 3.58 | O187: =IF(F187=0,"",G187/F187) | P187: =IF(H187>0,1,0) -> 0 | Q187: =IF(G187=0,1,0) -> 0 | R187: =TEXT(A187,"mmm") -> Jul | S187: =WEEKNUM(A187,2) -> 27 | T187: =IF(A187<DATE(2026,6,30),"1-Pre-outage",IF(A187<DATE(2026,7,5),"2-Transition","3-Outage-heavy")) -> 2-Transition | U187: =IF(K187="","",IF(ISNUMBER(SEARCH("TURBINE",K187)),"Turbine",IF(ISNUMBER(SEARCH("GENERATOR",K187)),"Generator",IF(ISNUMBER(SEARCH("BOILER",K187)),"Boiler",IF(ISNUMBER(SEARCH("AIR PREHEATER",K187)),"Auxiliary",IF(ISNUMBER(SEARCH("ELECTRICAL",K187)),"Electrical","Other")))))) | V187: =AVERAGEIFS(G:G,B:B,B187,H:H,0) -> 3.5358621 | W187: =IF(P187=1,MAX(0,V187-G187),0) -> 0
A188: 46205 | B188: 5 | C188: ="Unit "&B188 -> Unit 5 | E188: 210 | F188: 3.81 | G188: 4.08 | H188: 0 | L188: =E188*24/1000 -> 5.04 | M188: =G188/L188 -> 0.80952381 | N188: =G188-F188 -> 0.27 | O188: =IF(F188=0,"",G188/F188) -> 1.0708661 | P188: =IF(H188>0,1,0) -> 0 | Q188: =IF(G188=0,1,0) -> 0 | R188: =TEXT(A188,"mmm") -> Jul | S188: =WEEKNUM(A188,2) -> 27 | T188: =IF(A188<DATE(2026,6,30),"1-Pre-outage",IF(A188<DATE(2026,7,5),"2-Transition","3-Outage-heavy")) -> 2-Transition | U188: =IF(K188="","",IF(ISNUMBER(SEARCH("TURBINE",K188)),"Turbine",IF(ISNUMBER(SEARCH("GENERATOR",K188)),"Generator",IF(ISNUMBER(SEARCH("BOILER",K188)),"Boiler",IF(ISNUMBER(SEARCH("AIR PREHEATER",K188)),"Auxiliary",IF(ISNUMBER(SEARCH("ELECTRICAL",K188)),"Electrical","Other")))))) | V188: =AVERAGEIFS(G:G,B:B,B188,H:H,0) -> 3.9888889 | W188: =IF(P188=1,MAX(0,V188-G188),0) -> 0
A189: 46205 | B189: 6 | C189: ="Unit "&B189 -> Unit 6 | E189: 195 | F189: 3.84 | G189: 3.85 | H189: 0 | L189: =E189*24/1000 -> 4.68 | M189: =G189/L189 -> 0.82264957 | N189: =G189-F189 -> 0.01 | O189: =IF(F189=0,"",G189/F189) -> 1.0026042 | P189: =IF(H189>0,1,0) -> 0 | Q189: =IF(G189=0,1,0) -> 0 | R189: =TEXT(A189,"mmm") -> Jul | S189: =WEEKNUM(A189,2) -> 27 | T189: =IF(A189<DATE(2026,6,30),"1-Pre-outage",IF(A189<DATE(2026,7,5),"2-Transition","3-Outage-heavy")) -> 2-Transition | U189: =IF(K189="","",IF(ISNUMBER(SEARCH("TURBINE",K189)),"Turbine",IF(ISNUMBER(SEARCH("GENERATOR",K189)),"Generator",IF(ISNUMBER(SEARCH("BOILER",K189)),"Boiler",IF(ISNUMBER(SEARCH("AIR PREHEATER",K189)),"Auxiliary",IF(ISNUMBER(SEARCH("ELECTRICAL",K189)),"Electrical","Other")))))) | V189: =AVERAGEIFS(G:G,B:B,B189,H:H,0) -> 3.8537778 | W189: =IF(P189=1,MAX(0,V189-G189),0) -> 0
A190: 46205 | B190: 7 | C190: ="Unit "&B190 -> Unit 7 | E190: 195 | F190: 0 | G190: 4.07 | H190: 0 | L190: =E190*24/1000 -> 4.68 | M190: =G190/L190 -> 0.86965812 | N190: =G190-F190 -> 4.07 | O190: =IF(F190=0,"",G190/F190) | P190: =IF(H190>0,1,0) -> 0 | Q190: =IF(G190=0,1,0) -> 0 | R190: =TEXT(A190,"mmm") -> Jul | S190: =WEEKNUM(A190,2) -> 27 | T190: =IF(A190<DATE(2026,6,30),"1-Pre-outage",IF(A190<DATE(2026,7,5),"2-Transition","3-Outage-heavy")) -> 2-Transition | U190: =IF(K190="","",IF(ISNUMBER(SEARCH("TURBINE",K190)),"Turbine",IF(ISNUMBER(SEARCH("GENERATOR",K190)),"Generator",IF(ISNUMBER(SEARCH("BOILER",K190)),"Boiler",IF(ISNUMBER(SEARCH("AIR PREHEATER",K190)),"Auxiliary",IF(ISNUMBER(SEARCH("ELECTRICAL",K190)),"Electrical","Other")))))) | V190: =AVERAGEIFS(G:G,B:B,B190,H:H,0) -> 3.98375 | W190: =IF(P190=1,MAX(0,V190-G190),0) -> 0
A191: 46206 | B191: 1 | C191: ="Unit "&B191 -> Unit 1 | E191: 110 | F191: 1.84 | G191: 1.54 | H191: 0 | L191: =E191*24/1000 -> 2.64 | M191: =G191/L191 -> 0.58333333 | N191: =G191-F191 -> -0.3 | O191: =IF(F191=0,"",G191/F191) -> 0.83695652 | P191: =IF(H191>0,1,0) -> 0 | Q191: =IF(G191=0,1,0) -> 0 | R191: =TEXT(A191,"mmm") -> Jul | S191: =WEEKNUM(A191,2) -> 27 | T191: =IF(A191<DATE(2026,6,30),"1-Pre-outage",IF(A191<DATE(2026,7,5),"2-Transition","3-Outage-heavy")) -> 2-Transition | U191: =IF(K191="","",IF(ISNUMBER(SEARCH("TURBINE",K191)),"Turbine",IF(ISNUMBER(SEARCH("GENERATOR",K191)),"Generator",IF(ISNUMBER(SEARCH("BOILER",K191)),"Boiler",IF(ISNUMBER(SEARCH("AIR PREHEATER",K191)),"Auxiliary",IF(ISNUMBER(SEARCH("ELECTRICAL",K191)),"Electrical","Other")))))) | V191: =AVERAGEIFS(G:G,B:B,B191,H:H,0) -> 1.6118182 | W191: =IF(P191=1,MAX(0,V191-G191),0) -> 0
A192: 46206 | B192: 2 | C192: ="Unit "&B192 -> Unit 2 | E192: 110 | F192: 1.87 | G192: 1.58 | H192: 0 | L192: =E192*24/1000 -> 2.64 | M192: =G192/L192 -> 0.59848485 | N192: =G192-F192 -> -0.29 | O192: =IF(F192=0,"",G192/F192) -> 0.84491979 | P192: =IF(H192>0,1,0) -> 0 | Q192: =IF(G192=0,1,0) -> 0 | R192: =TEXT(A192,"mmm") -> Jul | S192: =WEEKNUM(A192,2) -> 27 | T192: =IF(A192<DATE(2026,6,30),"1-Pre-outage",IF(A192<DATE(2026,7,5),"2-Transition","3-Outage-heavy")) -> 2-Transition | U192: =IF(K192="","",IF(ISNUMBER(SEARCH("TURBINE",K192)),"Turbine",IF(ISNUMBER(SEARCH("GENERATOR",K192)),"Generator",IF(ISNUMBER(SEARCH("BOILER",K192)),"Boiler",IF(ISNUMBER(SEARCH("AIR PREHEATER",K192)),"Auxiliary",IF(ISNUMBER(SEARCH("ELECTRICAL",K192)),"Electrical","Other")))))) | V192: =AVERAGEIFS(G:G,B:B,B192,H:H,0) -> 1.6795556 | W192: =IF(P192=1,MAX(0,V192-G192),0) -> 0
A193: 46206 | B193: 3 | C193: ="Unit "&B193 -> Unit 3 | E193: 210 | F193: 3.67 | G193: 3.59 | H193: 0 | L193: =E193*24/1000 -> 5.04 | M193: =G193/L193 -> 0.71230159 | N193: =G193-F193 -> -0.08 | O193: =IF(F193=0,"",G193/F193) -> 0.97820163 | P193: =IF(H193>0,1,0) -> 0 | Q193: =IF(G193=0,1,0) -> 0 | R193: =TEXT(A193,"mmm") -> Jul | S193: =WEEKNUM(A193,2) -> 27 | T193: =IF(A193<DATE(2026,6,30),"1-Pre-outage",IF(A193<DATE(2026,7,5),"2-Transition","3-Outage-heavy")) -> 2-Transition | U193: =IF(K193="","",IF(ISNUMBER(SEARCH("TURBINE",K193)),"Turbine",IF(ISNUMBER(SEARCH("GENERATOR",K193)),"Generator",IF(ISNUMBER(SEARCH("BOILER",K193)),"Boiler",IF(ISNUMBER(SEARCH("AIR PREHEATER",K193)),"Auxiliary",IF(ISNUMBER(SEARCH("ELECTRICAL",K193)),"Electrical","Other")))))) | V193: =AVERAGEIFS(G:G,B:B,B193,H:H,0) -> 3.7269767 | W193: =IF(P193=1,MAX(0,V193-G193),0) -> 0
A194: 46206 | B194: 4 | C194: ="Unit "&B194 -> Unit 4 | E194: 210 | F194: 0 | G194: 3.17 | H194: 0 | L194: =E194*24/1000 -> 5.04 | M194: =G194/L194 -> 0.62896825 | N194: =G194-F194 -> 3.17 | O194: =IF(F194=0,"",G194/F194) | P194: =IF(H194>0,1,0) -> 0 | Q194: =IF(G194=0,1,0) -> 0 | R194: =TEXT(A194,"mmm") -> Jul | S194: =WEEKNUM(A194,2) -> 27 | T194: =IF(A194<DATE(2026,6,30),"1-Pre-outage",IF(A194<DATE(2026,7,5),"2-Transition","3-Outage-heavy")) -> 2-Transition | U194: =IF(K194="","",IF(ISNUMBER(SEARCH("TURBINE",K194)),"Turbine",IF(ISNUMBER(SEARCH("GENERATOR",K194)),"Generator",IF(ISNUMBER(SEARCH("BOILER",K194)),"Boiler",IF(ISNUMBER(SEARCH("AIR PREHEATER",K194)),"Auxiliary",IF(ISNUMBER(SEARCH("ELECTRICAL",K194)),"Electrical","Other")))))) | V194: =AVERAGEIFS(G:G,B:B,B194,H:H,0) -> 3.5358621 | W194: =IF(P194=1,MAX(0,V194-G194),0) -> 0
A195: 46206 | B195: 5 | C195: ="Unit "&B195 -> Unit 5 | E195: 210 | F195: 3.81 | G195: 3.88 | H195: 0 | L195: =E195*24/1000 -> 5.04 | M195: =G195/L195 -> 0.76984127 | N195: =G195-F195 -> 0.07 | O195: =IF(F195=0,"",G195/F195) -> 1.0183727 | P195: =IF(H195>0,1,0) -> 0 | Q195: =IF(G195=0,1,0) -> 0 | R195: =TEXT(A195,"mmm") -> Jul | S195: =WEEKNUM(A195,2) -> 27 | T195: =IF(A195<DATE(2026,6,30),"1-Pre-outage",IF(A195<DATE(2026,7,5),"2-Transition","3-Outage-heavy")) -> 2-Transition | U195: =IF(K195="","",IF(ISNUMBER(SEARCH("TURBINE",K195)),"Turbine",IF(ISNUMBER(SEARCH("GENERATOR",K195)),"Generator",IF(ISNUMBER(SEARCH("BOILER",K195)),"Boiler",IF(ISNUMBER(SEARCH("AIR PREHEATER",K195)),"Auxiliary",IF(ISNUMBER(SEARCH("ELECTRICAL",K195)),"Electrical","Other")))))) | V195: =AVERAGEIFS(G:G,B:B,B195,H:H,0) -> 3.9888889 | W195: =IF(P195=1,MAX(0,V195-G195),0) -> 0
... A207: 46208 | B207: 3 | C207: ="Unit "&B207 -> Unit 3 | E207: 210 | F207: 3.67 | G207: 3.52 | H207: 0 | L207: =E207*24/1000 -> 5.04 | M207: =G207/L207 -> 0.6984127 | N207: =G207-F207 -> -0.15 | O207: =IF(F207=0,"",G207/F207) -> 0.95912807 | P207: =IF(H207>0,1,0) -> 0 | Q207: =IF(G207=0,1,0) -> 0 | R207: =TEXT(A207,"mmm") -> Jul | S207: =WEEKNUM(A207,2) -> 27 | T207: =IF(A207<DATE(2026,6,30),"1-Pre-outage",IF(A207<DATE(2026,7,5),"2-Transition","3-Outage-heavy")) -> 3-Outage-heavy | U207: =IF(K207="","",IF(ISNUMBER(SEARCH("TURBINE",K207)),"Turbine",IF(ISNUMBER(SEARCH("GENERATOR",K207)),"Generator",IF(ISNUMBER(SEARCH("BOILER",K207)),"Boiler",IF(ISNUMBER(SEARCH("AIR PREHEATER",K207)),"Auxiliary",IF(ISNUMBER(SEARCH("ELECTRICAL",K207)),"Electrical","Other")))))) | V207: =AVERAGEIFS(G:G,B:B,B207,H:H,0) -> 3.7269767 | W207: =IF(P207=1,MAX(0,V207-G207),0) -> 0
A208: 46208 | B208: 4 | C208: ="Unit "&B208 -> Unit 4 | D208: S | E208: 210 | F208: 0 | G208: 0 | H208: 210 | I208: 46208 | K208: TURBINE BEARING PROBLEM | L208: =E208*24/1000 -> 5.04 | M208: =G208/L208 -> 0 | N208: =G208-F208 -> 0 | O208: =IF(F208=0,"",G208/F208) | P208: =IF(H208>0,1,0) -> 1 | Q208: =IF(G208=0,1,0) -> 1 | R208: =TEXT(A208,"mmm") -> Jul | S208: =WEEKNUM(A208,2) -> 27 | T208: =IF(A208<DATE(2026,6,30),"1-Pre-outage",IF(A208<DATE(2026,7,5),"2-Transition","3-Outage-heavy")) -> 3-Outage-heavy | U208: =IF(K208="","",IF(ISNUMBER(SEARCH("TURBINE",K208)),"Turbine",IF(ISNUMBER(SEARCH("GENERATOR",K208)),"Generator",IF(ISNUMBER(SEARCH("BOILER",K208)),"Boiler",IF(ISNUMBER(SEARCH("AIR PREHEATER",K208)),"Auxiliary",IF(ISNUMBER(SEARCH("ELECTRICAL",K208)),"Electrical","Other")))))) -> Turbine | V208: =AVERAGEIFS(G:G,B:B,B208,H:H,0) -> 3.5358621 | W208: =IF(P208=1,MAX(0,V208-G208),0) -> 3.5358621
A209: 46208 | B209: 5 | C209: ="Unit "&B209 -> Unit 5 | E209: 210 | F209: 3.81 | G209: 3.86 | H209: 0 | L209: =E209*24/1000 -> 5.04 | M209: =G209/L209 -> 0.76587302 | N209: =G209-F209 -> 0.05 | O209: =IF(F209=0,"",G209/F209) -> 1.0131234 | P209: =IF(H209>0,1,0) -> 0 | Q209: =IF(G209=0,1,0) -> 0 | R209: =TEXT(A209,"mmm") -> Jul | S209: =WEEKNUM(A209,2) -> 27 | T209: =IF(A209<DATE(2026,6,30),"1-Pre-outage",IF(A209<DATE(2026,7,5),"2-Transition","3-Outage-heavy")) -> 3-Outage-heavy | U209: =IF(K209="","",IF(ISNUMBER(SEARCH("TURBINE",K209)),"Turbine",IF(ISNUMBER(SEARCH("GENERATOR",K209)),"Generator",IF(ISNUMBER(SEARCH("BOILER",K209)),"Boiler",IF(ISNUMBER(SEARCH("AIR PREHEATER",K209)),"Auxiliary",IF(ISNUMBER(SEARCH("ELECTRICAL",K209)),"Electrical","Other")))))) | V209: =AVERAGEIFS(G:G,B:B,B209,H:H,0) -> 3.9888889 | W209: =IF(P209=1,MAX(0,V209-G209),0) -> 0
A210: 46208 | B210: 6 | C210: ="Unit "&B210 -> Unit 6 | E210: 195 | F210: 3.84 | G210: 3.82 | H210: 0 | L210: =E210*24/1000 -> 4.68 | M210: =G210/L210 -> 0.81623932 | N210: =G210-F210 -> -0.02 | O210: =IF(F210=0,"",G210/F210) -> 0.99479167 | P210: =IF(H210>0,1,0) -> 0 | Q210: =IF(G210=0,1,0) -> 0 | R210: =TEXT(A210,"mmm") -> Jul | S210: =WEEKNUM(A210,2) -> 27 | T210: =IF(A210<DATE(2026,6,30),"1-Pre-outage",IF(A210<DATE(2026,7,5),"2-Transition","3-Outage-heavy")) -> 3-Outage-heavy | U210: =IF(K210="","",IF(ISNUMBER(SEARCH("TURBINE",K210)),"Turbine",IF(ISNUMBER(SEARCH("GENERATOR",K210)),"Generator",IF(ISNUMBER(SEARCH("BOILER",K210)),"Boiler",IF(ISNUMBER(SEARCH("AIR PREHEATER",K210)),"Auxiliary",IF(ISNUMBER(SEARCH("ELECTRICAL",K210)),"Electrical","Other")))))) | V210: =AVERAGEIFS(G:G,B:B,B210,H:H,0) -> 3.8537778 | W210: =IF(P210=1,MAX(0,V210-G210),0) -> 0
A211: 46208 | B211: 7 | C211: ="Unit "&B211 -> Unit 7 | E211: 195 | F211: 0 | G211: 3.86 | H211: 0 | L211: =E211*24/1000 -> 4.68 | M211: =G211/L211 -> 0.82478632 | N211: =G211-F211 -> 3.86 | O211: =IF(F211=0,"",G211/F211) | P211: =IF(H211>0,1,0) -> 0 | Q211: =IF(G211=0,1,0) -> 0 | R211: =TEXT(A211,"mmm") -> Jul | S211: =WEEKNUM(A211,2) -> 27 | T211: =IF(A211<DATE(2026,6,30),"1-Pre-outage",IF(A211<DATE(2026,7,5),"2-Transition","3-Outage-heavy")) -> 3-Outage-heavy | U211: =IF(K211="","",IF(ISNUMBER(SEARCH("TURBINE",K211)),"Turbine",IF(ISNUMBER(SEARCH("GENERATOR",K211)),"Generator",IF(ISNUMBER(SEARCH("BOILER",K211)),"Boiler",IF(ISNUMBER(SEARCH("AIR PREHEATER",K211)),"Auxiliary",IF(ISNUMBER(SEARCH("ELECTRICAL",K211)),"Electrical","Other")))))) | V211: =AVERAGEIFS(G:G,B:B,B211,H:H,0) -> 3.98375 | W211: =IF(P211=1,MAX(0,V211-G211),0) -> 0
A212: 46209 | B212: 1 | C212: ="Unit "&B212 -> Unit 1 | D212: * | E212: 110 | F212: 1.84 | G212: 1.56 | H212: 0 | I212: 46209.557 | J212: 46209.663 | K212: ELECTRICAL MISCELLANEOUS PROBLEMS | L212: =E212*24/1000 -> 2.64 | M212: =G212/L212 -> 0.59090909 | N212: =G212-F212 -> -0.28 | O212: =IF(F212=0,"",G212/F212) -> 0.84782609 | P212: =IF(H212>0,1,0) -> 0 | Q212: =IF(G212=0,1,0) -> 0 | R212: =TEXT(A212,"mmm") -> Jul | S212: =WEEKNUM(A212,2) -> 28 | T212: =IF(A212<DATE(2026,6,30),"1-Pre-outage",IF(A212<DATE(2026,7,5),"2-Transition","3-Outage-heavy")) -> 3-Outage-heavy | U212: =IF(K212="","",IF(ISNUMBER(SEARCH("TURBINE",K212)),"Turbine",IF(ISNUMBER(SEARCH("GENERATOR",K212)),"Generator",IF(ISNUMBER(SEARCH("BOILER",K212)),"Boiler",IF(ISNUMBER(SEARCH("AIR PREHEATER",K212)),"Auxiliary",IF(ISNUMBER(SEARCH("ELECTRICAL",K212)),"Electrical","Other")))))) -> Electrical | V212: =AVERAGEIFS(G:G,B:B,B212,H:H,0) -> 1.6118182 | W212: =IF(P212=1,MAX(0,V212-G212),0) -> 0
...

Sheet Station_Daily
A1: Date | B1: Capacity_MW | C1: Program_MU | D1: Actual_MU | E1: Coal_Stock_Days | F1: Outage_MW | G1: Remarks | H1: Max_Possible_MU | I1: PLF | J1: Variance_MU | K1: Achievement | L1: Capacity_Available_Pct | M1: Phase | N1: Actual_7D_Avg | O1: Coal_Change_Days | P1: Check_vs_Units
A2: 46179 | B2: 1240 | C2: 23.96 | D2: 22.22 | E2: 15 | F2: 0 | H2: =B2*24/1000 -> 29.76 | I2: =D2/H2 -> 0.74663978 | J2: =D2-C2 -> -1.74 | K2: =IF(C2=0,"",D2/C2) -> 0.92737896 | L2: =(B2-F2)/B2 -> 1 | M2: =IF(A2<DATE(2026,6,30),"1-Pre-outage",IF(A2<DATE(2026,7,5),"2-Transition","3-Outage-heavy")) -> 1-Pre-outage | P2: =ROUND(SUMIFS(Unit_Daily!G:G,Unit_Daily!A:A,A2)-D2,2) -> 0
A3: 46180 | B3: 1240 | C3: 23.96 | D3: 21.88 | E3: 14 | F3: 0 | H3: =B3*24/1000 -> 29.76 | I3: =D3/H3 -> 0.73521505 | J3: =D3-C3 -> -2.08 | K3: =IF(C3=0,"",D3/C3) -> 0.91318865 | L3: =(B3-F3)/B3 -> 1 | M3: =IF(A3<DATE(2026,6,30),"1-Pre-outage",IF(A3<DATE(2026,7,5),"2-Transition","3-Outage-heavy")) -> 1-Pre-outage | O3: =E3-E2 -> -1 | P3: =ROUND(SUMIFS(Unit_Daily!G:G,Unit_Daily!A:A,A3)-D3,2) -> 0
A4: 46181 | B4: 1240 | C4: 23.96 | D4: 21.95 | E4: 14 | F4: 0 | H4: =B4*24/1000 -> 29.76 | I4: =D4/H4 -> 0.7375672 | J4: =D4-C4 -> -2.01 | K4: =IF(C4=0,"",D4/C4) -> 0.91611018 | L4: =(B4-F4)/B4 -> 1 | M4: =IF(A4<DATE(2026,6,30),"1-Pre-outage",IF(A4<DATE(2026,7,5),"2-Transition","3-Outage-heavy")) -> 1-Pre-outage | O4: =E4-E3 -> 0 | P4: =ROUND(SUMIFS(Unit_Daily!G:G,Unit_Daily!A:A,A4)-D4,2) -> 0
A5: 46182 | B5: 1240 | C5: 23.96 | D5: 22.45 | E5: 14 | F5: 0 | H5: =B5*24/1000 -> 29.76 | I5: =D5/H5 -> 0.75436828 | J5: =D5-C5 -> -1.51 | K5: =IF(C5=0,"",D5/C5) -> 0.9369783 | L5: =(B5-F5)/B5 -> 1 | M5: =IF(A5<DATE(2026,6,30),"1-Pre-outage",IF(A5<DATE(2026,7,5),"2-Transition","3-Outage-heavy")) -> 1-Pre-outage | O5: =E5-E4 -> 0 | P5: =ROUND(SUMIFS(Unit_Daily!G:G,Unit_Daily!A:A,A5)-D5,2) -> 0
A6: 46183 | B6: 1240 | C6: 23.96 | D6: 22.6 | E6: 14 | F6: 0 | H6: =B6*24/1000 -> 29.76 | I6: =D6/H6 -> 0.7594086 | J6: =D6-C6 -> -1.36 | K6: =IF(C6=0,"",D6/C6) -> 0.94323873 | L6: =(B6-F6)/B6 -> 1 | M6: =IF(A6<DATE(2026,6,30),"1-Pre-outage",IF(A6<DATE(2026,7,5),"2-Transition","3-Outage-heavy")) -> 1-Pre-outage | O6: =E6-E5 -> 0 | P6: =ROUND(SUMIFS(Unit_Daily!G:G,Unit_Daily!A:A,A6)-D6,2) -> 0
A7: 46184 | B7: 1240 | C7: 23.96 | D7: 22.28 | E7: 14 | F7: 0 | H7: =B7*24/1000 -> 29.76 | I7: =D7/H7 -> 0.74865591 | J7: =D7-C7 -> -1.68 | K7: =IF(C7=0,"",D7/C7) -> 0.92988314 | L7: =(B7-F7)/B7 -> 1 | M7: =IF(A7<DATE(2026,6,30),"1-Pre-outage",IF(A7<DATE(2026,7,5),"2-Transition","3-Outage-heavy")) -> 1-Pre-outage | O7: =E7-E6 -> 0 | P7: =ROUND(SUMIFS(Unit_Daily!G:G,Unit_Daily!A:A,A7)-D7,2) -> 0
A8: 46185 | B8: 1240 | C8: 23.96 | D8: 21.58 | E8: 14 | F8: 0 | H8: =B8*24/1000 -> 29.76 | I8: =D8/H8 -> 0.72513441 | J8: =D8-C8 -> -2.38 | K8: =IF(C8=0,"",D8/C8) -> 0.90066778 | L8: =(B8-F8)/B8 -> 1 | M8: =IF(A8<DATE(2026,6,30),"1-Pre-outage",IF(A8<DATE(2026,7,5),"2-Transition","3-Outage-heavy")) -> 1-Pre-outage | N8: =AVERAGE(D2:D8) -> 22.137143 | O8: =E8-E7 -> 0 | P8: =ROUND(SUMIFS(Unit_Daily!G:G,Unit_Daily!A:A,A8)-D8,2) -> 0
A9: 46186 | B9: 1240 | C9: 23.96 | D9: 21.74 | E9: 14 | F9: 0 | H9: =B9*24/1000 -> 29.76 | I9: =D9/H9 -> 0.73051075 | J9: =D9-C9 -> -2.22 | K9: =IF(C9=0,"",D9/C9) -> 0.90734558 | L9: =(B9-F9)/B9 -> 1 | M9: =IF(A9<DATE(2026,6,30),"1-Pre-outage",IF(A9<DATE(2026,7,5),"2-Transition","3-Outage-heavy")) -> 1-Pre-outage | N9: =AVERAGE(D3:D9) -> 22.068571 | O9: =E9-E8 -> 0 | P9: =ROUND(SUMIFS(Unit_Daily!G:G,Unit_Daily!A:A,A9)-D9,2) -> 0
A10: 46187 | B10: 1240 | C10: 23.96 | D10: 21.02 | E10: 13 | F10: 0 | H10: =B10*24/1000 -> 29.76 | I10: =D10/H10 -> 0.7063172 | J10: =D10-C10 -> -2.94 | K10: =IF(C10=0,"",D10/C10) -> 0.87729549 | L10: =(B10-F10)/B10 -> 1 | M10: =IF(A10<DATE(2026,6,30),"1-Pre-outage",IF(A10<DATE(2026,7,5),"2-Transition","3-Outage-heavy")) -> 1-Pre-outage | N10: =AVERAGE(D4:D10) -> 21.945714 | O10: =E10-E9 -> -1 | P10: =ROUND(SUMIFS(Unit_Daily!G:G,Unit_Daily!A:A,A10)-D10,2) -> 0
A11: 46188 | B11: 1240 | C11: 19.96 | D11: 21.3 | E11: 13 | F11: 0 | H11: =B11*24/1000 -> 29.76 | I11: =D11/H11 -> 0.71572581 | J11: =D11-C11 -> 1.34 | K11: =IF(C11=0,"",D11/C11) -> 1.0671343 | L11: =(B11-F11)/B11 -> 1 | M11: =IF(A11<DATE(2026,6,30),"1-Pre-outage",IF(A11<DATE(2026,7,5),"2-Transition","3-Outage-heavy")) -> 1-Pre-outage | N11: =AVERAGE(D5:D11) -> 21.852857 | O11: =E11-E10 -> 0 | P11: =ROUND(SUMIFS(Unit_Daily!G:G,Unit_Daily!A:A,A11)-D11,2) -> 0
A12: 46189 | B12: 1240 | C12: 19.96 | D12: 22.49 | E12: 13 | F12: 0 | H12: =B12*24/1000 -> 29.76 | I12: =D12/H12 -> 0.75571237 | J12: =D12-C12 -> 2.53 | K12: =IF(C12=0,"",D12/C12) -> 1.1267535 | L12: =(B12-F12)/B12 -> 1 | M12: =IF(A12<DATE(2026,6,30),"1-Pre-outage",IF(A12<DATE(2026,7,5),"2-Transition","3-Outage-heavy")) -> 1-Pre-outage | N12: =AVERAGE(D6:D12) -> 21.858571 | O12: =E12-E11 -> 0 | P12: =ROUND(SUMIFS(Unit_Daily!G:G,Unit_Daily!A:A,A12)-D12,2) -> 0
A13: 46190 | B13: 1240 | C13: 19.96 | D13: 22.35 | E13: 13 | F13: 0 | H13: =B13*24/1000 -> 29.76 | I13: =D13/H13 -> 0.75100806 | J13: =D13-C13 -> 2.39 | K13: =IF(C13=0,"",D13/C13) -> 1.1197395 | L13: =(B13-F13)/B13 -> 1 | M13: =IF(A13<DATE(2026,6,30),"1-Pre-outage",IF(A13<DATE(2026,7,5),"2-Transition","3-Outage-heavy")) -> 1-Pre-outage | N13: =AVERAGE(D7:D13) -> 21.822857 | O13: =E13-E12 -> 0 | P13: =ROUND(SUMIFS(Unit_Daily!G:G,Unit_Daily!A:A,A13)-D13,2) -> 0
A14: 46191 | B14: 1240 | C14: 19.96 | D14: 23.1 | E14: 13 | F14: 0 | H14: =B14*24/1000 -> 29.76 | I14: =D14/H14 -> 0.77620968 | J14: =D14-C14 -> 3.14 | K14: =IF(C14=0,"",D14/C14) -> 1.1573146 | L14: =(B14-F14)/B14 -> 1 | M14: =IF(A14<DATE(2026,6,30),"1-Pre-outage",IF(A14<DATE(2026,7,5),"2-Transition","3-Outage-heavy")) -> 1-Pre-outage | N14: =AVERAGE(D8:D14) -> 21.94 | O14: =E14-E13 -> 0 | P14: =ROUND(SUMIFS(Unit_Daily!G:G,Unit_Daily!A:A,A14)-D14,2) -> 0
A15: 46192 | B15: 1240 | C15: 19.96 | D15: 23.03 | E15: 13 | F15: 0 | H15: =B15*24/1000 -> 29.76 | I15: =D15/H15 -> 0.77385753 | J15: =D15-C15 -> 3.07 | K15: =IF(C15=0,"",D15/C15) -> 1.1538076 | L15: =(B15-F15)/B15 -> 1 | M15: =IF(A15<DATE(2026,6,30),"1-Pre-outage",IF(A15<DATE(2026,7,5),"2-Transition","3-Outage-heavy")) -> 1-Pre-outage | N15: =AVERAGE(D9:D15) -> 22.147143 | O15: =E15-E14 -> 0 | P15: =ROUND(SUMIFS(Unit_Daily!G:G,Unit_Daily!A:A,A15)-D15,2) -> 0
A16: 46193 | B16: 1240 | C16: 19.96 | D16: 23.61 | E16: 12 | F16: 0 | H16: =B16*24/1000 -> 29.76 | I16: =D16/H16 -> 0.79334677 | J16: =D16-C16 -> 3.65 | K16: =IF(C16=0,"",D16/C16) -> 1.1828657 | L16: =(B16-F16)/B16 -> 1 | M16: =IF(A16<DATE(2026,6,30),"1-Pre-outage",IF(A16<DATE(2026,7,5),"2-Transition","3-Outage-heavy")) -> 1-Pre-outage | N16: =AVERAGE(D10:D16) -> 22.414286 | O16: =E16-E15 -> -1 | P16: =ROUND(SUMIFS(Unit_Daily!G:G,Unit_Daily!A:A,A16)-D16,2) -> 0
A17: 46194 | B17: 1240 | C17: 19.96 | D17: 21.8 | E17: 13 | F17: 0 | H17: =B17*24/1000 -> 29.76 | I17: =D17/H17 -> 0.73252688 | J17: =D17-C17 -> 1.84 | K17: =IF(C17=0,"",D17/C17) -> 1.0921844 | L17: =(B17-F17)/B17 -> 1 | M17: =IF(A17<DATE(2026,6,30),"1-Pre-outage",IF(A17<DATE(2026,7,5),"2-Transition","3-Outage-heavy")) -> 1-Pre-outage | N17: =AVERAGE(D11:D17) -> 22.525714 | O17: =E17-E16 -> 1 | P17: =ROUND(SUMIFS(Unit_Daily!G:G,Unit_Daily!A:A,A17)-D17,2) -> 0
A18: 46195 | B18: 1240 | C18: 19.96 | D18: 21.79 | E18: 12 | F18: 0 | H18: =B18*24/1000 -> 29.76 | I18: =D18/H18 -> 0.73219086 | J18: =D18-C18 -> 1.83 | K18: =IF(C18=0,"",D18/C18) -> 1.0916834 | L18: =(B18-F18)/B18 -> 1 | M18: =IF(A18<DATE(2026,6,30),"1-Pre-outage",IF(A18<DATE(2026,7,5),"2-Transition","3-Outage-heavy")) -> 1-Pre-outage | N18: =AVERAGE(D12:D18) -> 22.595714 | O18: =E18-E17 -> -1 | P18: =ROUND(SUMIFS(Unit_Daily!G:G,Unit_Daily!A:A,A18)-D18,2) -> 0
A19: 46196 | B19: 1240 | C19: 19.96 | D19: 22.3 | E19: 12 | F19: 0 | H19: =B19*24/1000 -> 29.76 | I19: =D19/H19 -> 0.74932796 | J19: =D19-C19 -> 2.34 | K19: =IF(C19=0,"",D19/C19) -> 1.1172345 | L19: =(B19-F19)/B19 -> 1 | M19: =IF(A19<DATE(2026,6,30),"1-Pre-outage",IF(A19<DATE(2026,7,5),"2-Transition","3-Outage-heavy")) -> 1-Pre-outage | N19: =AVERAGE(D13:D19) -> 22.568571 | O19: =E19-E18 -> 0 | P19: =ROUND(SUMIFS(Unit_Daily!G:G,Unit_Daily!A:A,A19)-D19,2) -> 0
... A46: 46223 | B46: 1240 | C46: 11.36 | D46: 18.24 | E46: 15 | F46: 320 | H46: =B46*24/1000 -> 29.76 | I46: =D46/H46 -> 0.61290323 | J46: =D46-C46 -> 6.88 | K46: =IF(C46=0,"",D46/C46) -> 1.6056338 | L46: =(B46-F46)/B46 -> 0.74193548 | M46: =IF(A46<DATE(2026,6,30),"1-Pre-outage",IF(A46<DATE(2026,7,5),"2-Transition","3-Outage-heavy")) -> 3-Outage-heavy | N46: =AVERAGE(D40:D46) -> 17.062857 | O46: =E46-E45 -> 0 | P46: =ROUND(SUMIFS(Unit_Daily!G:G,Unit_Daily!A:A,A46)-D46,2) -> 0

Sheet Unit_Reference
A1: Unit | B1: Monitored Capacity (MW)
A2: Unit 1 | B2: 110
A3: Unit 2 | B3: 110
A4: Unit 3 | B4: 210
A5: Unit 4 | B5: 210
A6: Unit 5 | B6: 210
A7: Unit 6 | B7: 195
A8: Unit 7 | B8: 195
A9: Station Total | B9: 1240

Sheet Data_Quality
A1: Check | B1: Result
A2: Expected date range | B2: 06-Jun-2026 to 20-Jul-2026
A3: Expected daily files | B3: 45
A4: Daily files successfully parsed | B4: 45
A5: Expected Kota records (8 x 45) | B5: 360
A6: Kota records extracted | B6: 360
A7: Missing source files | B7: 0
A8: Data-quality flags | B8: 0

Sheet Data_Dictionary
A1: Sheet | B1: Field | C1: Meaning | D1: How calculated / source
A2: Unit_Daily | B2: Date | C2: Calendar date of the daily report | D2: Raw, from NPP Report 02
A3: Unit_Daily | B3: Unit | C3: Unit number 1-7 | D3: Raw
A4: Unit_Daily | B4: Unit_Label | C4: Text label e.g. "Unit 1" | D4: Concatenates "Unit " with the Unit number
A5: Unit_Daily | B5: Status | C5: Status code on the report (S = under outage, * = day unit resynced). Confirm against NPP legend. | D5: Raw
A6: Unit_Daily | B6: Capacity_MW | C6: Installed/monitored capacity of the unit | D6: Raw
A7: Unit_Daily | B7: Program_MU | C7: Scheduled generation target for the day (million units) | D7: Raw
A8: Unit_Daily | B8: Actual_MU | C8: Actual generation for the day (million units) | D8: Raw
A9: Unit_Daily | B9: Outage_MW | C9: Capacity under outage that day | D9: Raw
A10: Unit_Daily | B10: Outage_DateTime / Sync_DateTime | C10: When the outage started / unit resynced | D10: Raw
A11: Unit_Daily | B11: Remarks | C11: Reason for outage, free text | D11: Raw
A12: Unit_Daily | B12: Max_Possible_MU | C12: Max possible generation if running at full capacity all day | D12: Capacity_MW*24/1000
... A27: All | B27: Phase definition | C27: 1-Pre-outage: 6-29 Jun | 2-Transition: 30 Jun-4 Jul | 3-Outage-heavy: 5-20 Jul | D27: Chosen from the outage pattern in this dataset
A29: LIMITATIONS
A30: • No heat rate, fuel/coal consumption, or auxiliary power consumption data is present, so true thermal efficiency cannot be calculated from this dataset.
A31: • Only 45 days of data (6 Jun - 20 Jul 2026) — not enough to draw seasonal conclusions.
A32: • Est_Loss_MU is an analyst estimate against each unit's own baseline, not an official utility-reported loss figure.
A33: • Status code meanings (S, *) are inferred from the pattern in the data and should be confirmed against the official NPP report legend.
